[2024-12-15T15:32:10.124-0500] {taskinstance.py:1159} INFO - Dependencies all met for dep_context=non-requeueable deps ti=<TaskInstance: daily_price_volume_etl.retry_fetch_raw_data manual__2024-12-15T20:29:32.493974+00:00 [queued]>
[2024-12-15T15:32:10.133-0500] {taskinstance.py:1159} INFO - Dependencies all met for dep_context=requeueable deps ti=<TaskInstance: daily_price_volume_etl.retry_fetch_raw_data manual__2024-12-15T20:29:32.493974+00:00 [queued]>
[2024-12-15T15:32:10.133-0500] {taskinstance.py:1361} INFO - Starting attempt 1 of 3
[2024-12-15T15:32:10.140-0500] {taskinstance.py:1382} INFO - Executing <Task(PythonOperator): retry_fetch_raw_data> on 2024-12-15 20:29:32.493974+00:00
[2024-12-15T15:32:10.143-0500] {standard_task_runner.py:57} INFO - Started process 1632 to run task
[2024-12-15T15:32:10.146-0500] {standard_task_runner.py:84} INFO - Running: ['***', 'tasks', 'run', 'daily_price_volume_etl', 'retry_fetch_raw_data', 'manual__2024-12-15T20:29:32.493974+00:00', '--job-id', '415', '--raw', '--subdir', 'DAGS_FOLDER/etl_dag.py', '--cfg-path', '/tmp/tmpgyhkmpky']
[2024-12-15T15:32:10.148-0500] {standard_task_runner.py:85} INFO - Job 415: Subtask retry_fetch_raw_data
[2024-12-15T15:32:10.174-0500] {task_command.py:416} INFO - Running <TaskInstance: daily_price_volume_etl.retry_fetch_raw_data manual__2024-12-15T20:29:32.493974+00:00 [running]> on host c8ba26a29f48
[2024-12-15T15:32:10.226-0500] {taskinstance.py:1662} INFO - Exporting env vars: AIRFLOW_CTX_DAG_OWNER='***' AIRFLOW_CTX_DAG_ID='daily_price_volume_etl' AIRFLOW_CTX_TASK_ID='retry_fetch_raw_data' AIRFLOW_CTX_EXECUTION_DATE='2024-12-15T20:29:32.493974+00:00' AIRFLOW_CTX_TRY_NUMBER='1' AIRFLOW_CTX_DAG_RUN_ID='manual__2024-12-15T20:29:32.493974+00:00'
[2024-12-15T15:32:10.227-0500] {taskinstance.py:1937} ERROR - Task failed with exception
Traceback (most recent call last):
  File "/home/airflow/.local/lib/python3.8/site-packages/airflow/operators/python.py", line 192, in execute
    return_value = self.execute_callable()
  File "/home/airflow/.local/lib/python3.8/site-packages/airflow/operators/python.py", line 209, in execute_callable
    return self.python_callable(*self.op_args, **self.op_kwargs)
  File "/opt/airflow/dags/src/etl.py", line 395, in save_raw_data
    df = yfExtractObj.fetch_data(tickers=tickers, start_date=start_date, end_date=end_date)
  File "/opt/airflow/dags/src/etl.py", line 61, in fetch_data
    if not isinstance(tickers,list): raise ValueError("Input a list of tickers")
ValueError: Input a list of tickers
[2024-12-15T15:32:10.232-0500] {taskinstance.py:1400} INFO - Marking task as UP_FOR_RETRY. dag_id=daily_price_volume_etl, task_id=retry_fetch_raw_data, execution_date=20241215T202932, start_date=20241215T203210, end_date=20241215T203210
[2024-12-15T15:32:10.240-0500] {standard_task_runner.py:104} ERROR - Failed to execute job 415 for task retry_fetch_raw_data (Input a list of tickers; 1632)
[2024-12-15T15:32:10.249-0500] {local_task_job_runner.py:228} INFO - Task exited with return code 1
