[2024-12-14T04:44:08.136+0000] {taskinstance.py:1159} INFO - Dependencies all met for dep_context=non-requeueable deps ti=<TaskInstance: create_daily_price_volume_table.load_data scheduled__2024-12-13T04:44:03.796181+00:00 [queued]>
[2024-12-14T04:44:08.140+0000] {taskinstance.py:1159} INFO - Dependencies all met for dep_context=requeueable deps ti=<TaskInstance: create_daily_price_volume_table.load_data scheduled__2024-12-13T04:44:03.796181+00:00 [queued]>
[2024-12-14T04:44:08.140+0000] {taskinstance.py:1361} INFO - Starting attempt 1 of 2
[2024-12-14T04:44:08.146+0000] {taskinstance.py:1382} INFO - Executing <Task(PythonOperator): load_data> on 2024-12-13 04:44:03.796181+00:00
[2024-12-14T04:44:08.150+0000] {standard_task_runner.py:57} INFO - Started process 396 to run task
[2024-12-14T04:44:08.152+0000] {standard_task_runner.py:84} INFO - Running: ['***', 'tasks', 'run', 'create_daily_price_volume_table', 'load_data', 'scheduled__2024-12-13T04:44:03.796181+00:00', '--job-id', '9', '--raw', '--subdir', 'DAGS_FOLDER/etl_dag.py', '--cfg-path', '/tmp/tmp8z8i8wwx']
[2024-12-14T04:44:08.152+0000] {standard_task_runner.py:85} INFO - Job 9: Subtask load_data
[2024-12-14T04:44:08.173+0000] {task_command.py:416} INFO - Running <TaskInstance: create_daily_price_volume_table.load_data scheduled__2024-12-13T04:44:03.796181+00:00 [running]> on host f6f2451b973c
[2024-12-14T04:44:08.203+0000] {taskinstance.py:1662} INFO - Exporting env vars: AIRFLOW_CTX_DAG_OWNER='***' AIRFLOW_CTX_DAG_ID='create_daily_price_volume_table' AIRFLOW_CTX_TASK_ID='load_data' AIRFLOW_CTX_EXECUTION_DATE='2024-12-13T04:44:03.796181+00:00' AIRFLOW_CTX_TRY_NUMBER='1' AIRFLOW_CTX_DAG_RUN_ID='scheduled__2024-12-13T04:44:03.796181+00:00'
[2024-12-14T04:44:08.204+0000] {taskinstance.py:1937} ERROR - Task failed with exception
Traceback (most recent call last):
  File "/home/airflow/.local/lib/python3.8/site-packages/airflow/operators/python.py", line 192, in execute
    return_value = self.execute_callable()
  File "/home/airflow/.local/lib/python3.8/site-packages/airflow/operators/python.py", line 209, in execute_callable
    return self.python_callable(*self.op_args, **self.op_kwargs)
TypeError: create_price_volume_table() missing 1 required positional argument: 'self'
[2024-12-14T04:44:08.208+0000] {taskinstance.py:1400} INFO - Marking task as UP_FOR_RETRY. dag_id=create_daily_price_volume_table, task_id=load_data, execution_date=20241213T044403, start_date=20241214T044408, end_date=20241214T044408
[2024-12-14T04:44:08.216+0000] {standard_task_runner.py:104} ERROR - Failed to execute job 9 for task load_data (create_price_volume_table() missing 1 required positional argument: 'self'; 396)
[2024-12-14T04:44:08.250+0000] {local_task_job_runner.py:228} INFO - Task exited with return code 1
[2024-12-14T04:44:08.259+0000] {taskinstance.py:2778} INFO - 0 downstream tasks scheduled from follow-on schedule check
