[2024-12-14T21:47:35.275+0000] {taskinstance.py:1159} INFO - Dependencies all met for dep_context=non-requeueable deps ti=<TaskInstance: create_daily_price_volume_table.create_price_volume_table manual__2024-12-14T21:47:33.737939+00:00 [queued]>
[2024-12-14T21:47:35.280+0000] {taskinstance.py:1159} INFO - Dependencies all met for dep_context=requeueable deps ti=<TaskInstance: create_daily_price_volume_table.create_price_volume_table manual__2024-12-14T21:47:33.737939+00:00 [queued]>
[2024-12-14T21:47:35.280+0000] {taskinstance.py:1361} INFO - Starting attempt 1 of 2
[2024-12-14T21:47:35.288+0000] {taskinstance.py:1382} INFO - Executing <Task(PythonOperator): create_price_volume_table> on 2024-12-14 21:47:33.737939+00:00
[2024-12-14T21:47:35.291+0000] {standard_task_runner.py:57} INFO - Started process 84 to run task
[2024-12-14T21:47:35.294+0000] {standard_task_runner.py:84} INFO - Running: ['***', 'tasks', 'run', 'create_daily_price_volume_table', 'create_price_volume_table', 'manual__2024-12-14T21:47:33.737939+00:00', '--job-id', '4', '--raw', '--subdir', 'DAGS_FOLDER/etl_dag.py', '--cfg-path', '/tmp/tmp4yxgstlc']
[2024-12-14T21:47:35.295+0000] {standard_task_runner.py:85} INFO - Job 4: Subtask create_price_volume_table
[2024-12-14T21:47:35.318+0000] {task_command.py:416} INFO - Running <TaskInstance: create_daily_price_volume_table.create_price_volume_table manual__2024-12-14T21:47:33.737939+00:00 [running]> on host 2784adf275f7
[2024-12-14T21:47:35.356+0000] {taskinstance.py:1662} INFO - Exporting env vars: AIRFLOW_CTX_DAG_OWNER='***' AIRFLOW_CTX_DAG_ID='create_daily_price_volume_table' AIRFLOW_CTX_TASK_ID='create_price_volume_table' AIRFLOW_CTX_EXECUTION_DATE='2024-12-14T21:47:33.737939+00:00' AIRFLOW_CTX_TRY_NUMBER='1' AIRFLOW_CTX_DAG_RUN_ID='manual__2024-12-14T21:47:33.737939+00:00'
[2024-12-14T21:47:35.359+0000] {taskinstance.py:1937} ERROR - Task failed with exception
Traceback (most recent call last):
  File "/home/airflow/.local/lib/python3.8/site-packages/sqlalchemy/engine/base.py", line 1910, in _execute_context
    self.dialect.do_execute(
  File "/home/airflow/.local/lib/python3.8/site-packages/sqlalchemy/engine/default.py", line 736, in do_execute
    cursor.execute(statement, parameters)
  File "/home/airflow/.local/lib/python3.8/site-packages/pymysql/cursors.py", line 153, in execute
    result = self._query(query)
  File "/home/airflow/.local/lib/python3.8/site-packages/pymysql/cursors.py", line 322, in _query
    conn.query(q)
  File "/home/airflow/.local/lib/python3.8/site-packages/pymysql/connections.py", line 563, in query
    self._affected_rows = self._read_query_result(unbuffered=unbuffered)
  File "/home/airflow/.local/lib/python3.8/site-packages/pymysql/connections.py", line 825, in _read_query_result
    result.read()
  File "/home/airflow/.local/lib/python3.8/site-packages/pymysql/connections.py", line 1199, in read
    first_packet = self.connection._read_packet()
  File "/home/airflow/.local/lib/python3.8/site-packages/pymysql/connections.py", line 775, in _read_packet
    packet.raise_for_error()
  File "/home/airflow/.local/lib/python3.8/site-packages/pymysql/protocol.py", line 219, in raise_for_error
    err.raise_mysql_exception(self._data)
  File "/home/airflow/.local/lib/python3.8/site-packages/pymysql/err.py", line 150, in raise_mysql_exception
    raise errorclass(errno, errval)
pymysql.err.OperationalError: (1061, "Duplicate key name 'idx_ticker_date'")

The above exception was the direct cause of the following exception:

Traceback (most recent call last):
  File "/home/airflow/.local/lib/python3.8/site-packages/airflow/operators/python.py", line 192, in execute
    return_value = self.execute_callable()
  File "/home/airflow/.local/lib/python3.8/site-packages/airflow/operators/python.py", line 209, in execute_callable
    return self.python_callable(*self.op_args, **self.op_kwargs)
  File "/opt/airflow/dags/src/etl.py", line 158, in create_price_volume_table
    conn.execute(text(create_index_sql))
  File "/home/airflow/.local/lib/python3.8/site-packages/sqlalchemy/engine/base.py", line 1385, in execute
    return meth(self, multiparams, params, _EMPTY_EXECUTION_OPTS)
  File "/home/airflow/.local/lib/python3.8/site-packages/sqlalchemy/sql/elements.py", line 334, in _execute_on_connection
    return connection._execute_clauseelement(
  File "/home/airflow/.local/lib/python3.8/site-packages/sqlalchemy/engine/base.py", line 1577, in _execute_clauseelement
    ret = self._execute_context(
  File "/home/airflow/.local/lib/python3.8/site-packages/sqlalchemy/engine/base.py", line 1953, in _execute_context
    self._handle_dbapi_exception(
  File "/home/airflow/.local/lib/python3.8/site-packages/sqlalchemy/engine/base.py", line 2134, in _handle_dbapi_exception
    util.raise_(
  File "/home/airflow/.local/lib/python3.8/site-packages/sqlalchemy/util/compat.py", line 211, in raise_
    raise exception
  File "/home/airflow/.local/lib/python3.8/site-packages/sqlalchemy/engine/base.py", line 1910, in _execute_context
    self.dialect.do_execute(
  File "/home/airflow/.local/lib/python3.8/site-packages/sqlalchemy/engine/default.py", line 736, in do_execute
    cursor.execute(statement, parameters)
  File "/home/airflow/.local/lib/python3.8/site-packages/pymysql/cursors.py", line 153, in execute
    result = self._query(query)
  File "/home/airflow/.local/lib/python3.8/site-packages/pymysql/cursors.py", line 322, in _query
    conn.query(q)
  File "/home/airflow/.local/lib/python3.8/site-packages/pymysql/connections.py", line 563, in query
    self._affected_rows = self._read_query_result(unbuffered=unbuffered)
  File "/home/airflow/.local/lib/python3.8/site-packages/pymysql/connections.py", line 825, in _read_query_result
    result.read()
  File "/home/airflow/.local/lib/python3.8/site-packages/pymysql/connections.py", line 1199, in read
    first_packet = self.connection._read_packet()
  File "/home/airflow/.local/lib/python3.8/site-packages/pymysql/connections.py", line 775, in _read_packet
    packet.raise_for_error()
  File "/home/airflow/.local/lib/python3.8/site-packages/pymysql/protocol.py", line 219, in raise_for_error
    err.raise_mysql_exception(self._data)
  File "/home/airflow/.local/lib/python3.8/site-packages/pymysql/err.py", line 150, in raise_mysql_exception
    raise errorclass(errno, errval)
sqlalchemy.exc.OperationalError: (pymysql.err.OperationalError) (1061, "Duplicate key name 'idx_ticker_date'")
[SQL: CREATE INDEX idx_ticker_date ON price_volume (ticker, date);]
(Background on this error at: https://sqlalche.me/e/14/e3q8)
[2024-12-14T21:47:35.365+0000] {taskinstance.py:1400} INFO - Marking task as UP_FOR_RETRY. dag_id=create_daily_price_volume_table, task_id=create_price_volume_table, execution_date=20241214T214733, start_date=20241214T214735, end_date=20241214T214735
[2024-12-14T21:47:35.371+0000] {standard_task_runner.py:104} ERROR - Failed to execute job 4 for task create_price_volume_table ((pymysql.err.OperationalError) (1061, "Duplicate key name 'idx_ticker_date'")
[SQL: CREATE INDEX idx_ticker_date ON price_volume (ticker, date);]
(Background on this error at: https://sqlalche.me/e/14/e3q8); 84)
[2024-12-14T21:47:35.395+0000] {local_task_job_runner.py:228} INFO - Task exited with return code 1
[2024-12-14T21:47:35.402+0000] {taskinstance.py:2778} INFO - 0 downstream tasks scheduled from follow-on schedule check
