[2024-12-15T15:23:52.650-0500] {taskinstance.py:1159} INFO - Dependencies all met for dep_context=non-requeueable deps ti=<TaskInstance: daily_price_volume_etl.fetch_raw_data manual__2024-12-15T20:23:50.674160+00:00 [queued]>
[2024-12-15T15:23:52.655-0500] {taskinstance.py:1159} INFO - Dependencies all met for dep_context=requeueable deps ti=<TaskInstance: daily_price_volume_etl.fetch_raw_data manual__2024-12-15T20:23:50.674160+00:00 [queued]>
[2024-12-15T15:23:52.655-0500] {taskinstance.py:1361} INFO - Starting attempt 1 of 3
[2024-12-15T15:23:52.662-0500] {taskinstance.py:1382} INFO - Executing <Task(PythonOperator): fetch_raw_data> on 2024-12-15 20:23:50.674160+00:00
[2024-12-15T15:23:52.664-0500] {standard_task_runner.py:57} INFO - Started process 73 to run task
[2024-12-15T15:23:52.667-0500] {standard_task_runner.py:84} INFO - Running: ['***', 'tasks', 'run', 'daily_price_volume_etl', 'fetch_raw_data', 'manual__2024-12-15T20:23:50.674160+00:00', '--job-id', '408', '--raw', '--subdir', 'DAGS_FOLDER/etl_dag.py', '--cfg-path', '/tmp/tmpvq5dpj_w']
[2024-12-15T15:23:52.668-0500] {standard_task_runner.py:85} INFO - Job 408: Subtask fetch_raw_data
[2024-12-15T15:23:52.692-0500] {task_command.py:416} INFO - Running <TaskInstance: daily_price_volume_etl.fetch_raw_data manual__2024-12-15T20:23:50.674160+00:00 [running]> on host c8ba26a29f48
[2024-12-15T15:23:52.802-0500] {taskinstance.py:1662} INFO - Exporting env vars: AIRFLOW_CTX_DAG_OWNER='***' AIRFLOW_CTX_DAG_ID='daily_price_volume_etl' AIRFLOW_CTX_TASK_ID='fetch_raw_data' AIRFLOW_CTX_EXECUTION_DATE='2024-12-15T20:23:50.674160+00:00' AIRFLOW_CTX_TRY_NUMBER='1' AIRFLOW_CTX_DAG_RUN_ID='manual__2024-12-15T20:23:50.674160+00:00'
[2024-12-15T15:23:52.811-0500] {cache.py:130} INFO - Failed to create TzCache, reason: Error creating TzCache folder: '/home/***/.cache/py-yfinance' reason: [Errno 17] File exists: '/home/***/.cache/py-yfinance'. TzCache will not be used. Tip: You can direct cache to use a different location with 'set_tz_cache_location(mylocation)'
[2024-12-15T15:23:52.812-0500] {cache.py:130} INFO - Failed to create TzCache, reason: Error creating TzCache folder: '/home/***/.cache/py-yfinance' reason: [Errno 17] File exists: '/home/***/.cache/py-yfinance'. TzCache will not be used. Tip: You can direct cache to use a different location with 'set_tz_cache_location(mylocation)'
[2024-12-15T15:23:52.813-0500] {cache.py:130} INFO - Failed to create TzCache, reason: Error creating TzCache folder: '/home/***/.cache/py-yfinance' reason: [Errno 17] File exists: '/home/***/.cache/py-yfinance'. TzCache will not be used. Tip: You can direct cache to use a different location with 'set_tz_cache_location(mylocation)'
[2024-12-15T15:23:52.813-0500] {cache.py:130} INFO - Failed to create TzCache, reason: Error creating TzCache folder: '/home/***/.cache/py-yfinance' reason: [Errno 17] File exists: '/home/***/.cache/py-yfinance'. TzCache will not be used. Tip: You can direct cache to use a different location with 'set_tz_cache_location(mylocation)'
[2024-12-15T15:25:02.094-0500] {taskinstance.py:1937} ERROR - Task failed with exception
Traceback (most recent call last):
  File "/home/airflow/.local/lib/python3.8/site-packages/airflow/operators/python.py", line 192, in execute
    return_value = self.execute_callable()
  File "/home/airflow/.local/lib/python3.8/site-packages/airflow/operators/python.py", line 209, in execute_callable
    return self.python_callable(*self.op_args, **self.op_kwargs)
  File "/opt/airflow/dags/src/etl.py", line 398, in save_raw_data
    filename = str[kwargs["execution_date"]] + "raw_data.csv"
TypeError: 'type' object is not subscriptable
[2024-12-15T15:25:02.099-0500] {taskinstance.py:1400} INFO - Marking task as UP_FOR_RETRY. dag_id=daily_price_volume_etl, task_id=fetch_raw_data, execution_date=20241215T202350, start_date=20241215T202352, end_date=20241215T202502
[2024-12-15T15:25:02.105-0500] {standard_task_runner.py:104} ERROR - Failed to execute job 408 for task fetch_raw_data ('type' object is not subscriptable; 73)
[2024-12-15T15:25:02.128-0500] {local_task_job_runner.py:228} INFO - Task exited with return code 1
