[2024-12-15T00:18:19.560-0500] {taskinstance.py:1159} INFO - Dependencies all met for dep_context=non-requeueable deps ti=<TaskInstance: create_daily_price_volume_table.create_price_volume_table manual__2024-12-15T05:07:29.674028+00:00 [queued]>
[2024-12-15T00:18:19.566-0500] {taskinstance.py:1159} INFO - Dependencies all met for dep_context=requeueable deps ti=<TaskInstance: create_daily_price_volume_table.create_price_volume_table manual__2024-12-15T05:07:29.674028+00:00 [queued]>
[2024-12-15T00:18:19.567-0500] {taskinstance.py:1361} INFO - Starting attempt 3 of 3
[2024-12-15T00:18:19.573-0500] {taskinstance.py:1382} INFO - Executing <Task(PythonOperator): create_price_volume_table> on 2024-12-15 05:07:29.674028+00:00
[2024-12-15T00:18:19.576-0500] {standard_task_runner.py:57} INFO - Started process 162 to run task
[2024-12-15T00:18:19.578-0500] {standard_task_runner.py:84} INFO - Running: ['***', 'tasks', 'run', 'create_daily_price_volume_table', 'create_price_volume_table', 'manual__2024-12-15T05:07:29.674028+00:00', '--job-id', '286', '--raw', '--subdir', 'DAGS_FOLDER/etl_dag.py', '--cfg-path', '/tmp/tmp7z4m7fmw']
[2024-12-15T00:18:19.580-0500] {standard_task_runner.py:85} INFO - Job 286: Subtask create_price_volume_table
[2024-12-15T00:18:19.604-0500] {task_command.py:416} INFO - Running <TaskInstance: create_daily_price_volume_table.create_price_volume_table manual__2024-12-15T05:07:29.674028+00:00 [running]> on host 4f0221d9f38a
[2024-12-15T00:18:19.637-0500] {taskinstance.py:1662} INFO - Exporting env vars: AIRFLOW_CTX_DAG_OWNER='***' AIRFLOW_CTX_DAG_ID='create_daily_price_volume_table' AIRFLOW_CTX_TASK_ID='create_price_volume_table' AIRFLOW_CTX_EXECUTION_DATE='2024-12-15T05:07:29.674028+00:00' AIRFLOW_CTX_TRY_NUMBER='3' AIRFLOW_CTX_DAG_RUN_ID='manual__2024-12-15T05:07:29.674028+00:00'
[2024-12-15T00:18:19.641-0500] {taskinstance.py:1937} ERROR - Task failed with exception
Traceback (most recent call last):
  File "/home/airflow/.local/lib/python3.8/site-packages/sqlalchemy/engine/base.py", line 3371, in _wrap_pool_connect
    return fn()
  File "/home/airflow/.local/lib/python3.8/site-packages/sqlalchemy/pool/base.py", line 327, in connect
    return _ConnectionFairy._checkout(self)
  File "/home/airflow/.local/lib/python3.8/site-packages/sqlalchemy/pool/base.py", line 894, in _checkout
    fairy = _ConnectionRecord.checkout(pool)
  File "/home/airflow/.local/lib/python3.8/site-packages/sqlalchemy/pool/base.py", line 493, in checkout
    rec = pool._do_get()
  File "/home/airflow/.local/lib/python3.8/site-packages/sqlalchemy/pool/impl.py", line 146, in _do_get
    self._dec_overflow()
  File "/home/airflow/.local/lib/python3.8/site-packages/sqlalchemy/util/langhelpers.py", line 70, in __exit__
    compat.raise_(
  File "/home/airflow/.local/lib/python3.8/site-packages/sqlalchemy/util/compat.py", line 211, in raise_
    raise exception
  File "/home/airflow/.local/lib/python3.8/site-packages/sqlalchemy/pool/impl.py", line 143, in _do_get
    return self._create_connection()
  File "/home/airflow/.local/lib/python3.8/site-packages/sqlalchemy/pool/base.py", line 273, in _create_connection
    return _ConnectionRecord(self)
  File "/home/airflow/.local/lib/python3.8/site-packages/sqlalchemy/pool/base.py", line 388, in __init__
    self.__connect()
  File "/home/airflow/.local/lib/python3.8/site-packages/sqlalchemy/pool/base.py", line 691, in __connect
    pool.logger.debug("Error on connect(): %s", e)
  File "/home/airflow/.local/lib/python3.8/site-packages/sqlalchemy/util/langhelpers.py", line 70, in __exit__
    compat.raise_(
  File "/home/airflow/.local/lib/python3.8/site-packages/sqlalchemy/util/compat.py", line 211, in raise_
    raise exception
  File "/home/airflow/.local/lib/python3.8/site-packages/sqlalchemy/pool/base.py", line 686, in __connect
    self.dbapi_connection = connection = pool._invoke_creator(self)
  File "/home/airflow/.local/lib/python3.8/site-packages/sqlalchemy/engine/create.py", line 574, in connect
    return dialect.connect(*cargs, **cparams)
  File "/home/airflow/.local/lib/python3.8/site-packages/sqlalchemy/engine/default.py", line 598, in connect
    return self.dbapi.connect(*cargs, **cparams)
  File "/home/airflow/.local/lib/python3.8/site-packages/pymysql/connections.py", line 361, in __init__
    self.connect()
  File "/home/airflow/.local/lib/python3.8/site-packages/pymysql/connections.py", line 669, in connect
    self._request_authentication()
  File "/home/airflow/.local/lib/python3.8/site-packages/pymysql/connections.py", line 979, in _request_authentication
    auth_packet = _auth.caching_sha2_password_auth(self, auth_packet)
  File "/home/airflow/.local/lib/python3.8/site-packages/pymysql/_auth.py", line 268, in caching_sha2_password_auth
    pkt = _roundtrip(conn, data)
  File "/home/airflow/.local/lib/python3.8/site-packages/pymysql/_auth.py", line 121, in _roundtrip
    pkt = conn._read_packet()
  File "/home/airflow/.local/lib/python3.8/site-packages/pymysql/connections.py", line 775, in _read_packet
    packet.raise_for_error()
  File "/home/airflow/.local/lib/python3.8/site-packages/pymysql/protocol.py", line 219, in raise_for_error
    err.raise_mysql_exception(self._data)
  File "/home/airflow/.local/lib/python3.8/site-packages/pymysql/err.py", line 150, in raise_mysql_exception
    raise errorclass(errno, errval)
pymysql.err.OperationalError: (1045, "Access denied for user 'db_user'@'172.20.0.6' (using password: YES)")

The above exception was the direct cause of the following exception:

Traceback (most recent call last):
  File "/home/airflow/.local/lib/python3.8/site-packages/airflow/operators/python.py", line 192, in execute
    return_value = self.execute_callable()
  File "/home/airflow/.local/lib/python3.8/site-packages/airflow/operators/python.py", line 209, in execute_callable
    return self.python_callable(*self.op_args, **self.op_kwargs)
  File "/opt/airflow/dags/src/etl.py", line 270, in create_price_volume_table
    with self.engine.connect() as conn:
  File "/home/airflow/.local/lib/python3.8/site-packages/sqlalchemy/engine/base.py", line 3325, in connect
    return self._connection_cls(self, close_with_result=close_with_result)
  File "/home/airflow/.local/lib/python3.8/site-packages/sqlalchemy/engine/base.py", line 96, in __init__
    else engine.raw_connection()
  File "/home/airflow/.local/lib/python3.8/site-packages/sqlalchemy/engine/base.py", line 3404, in raw_connection
    return self._wrap_pool_connect(self.pool.connect, _connection)
  File "/home/airflow/.local/lib/python3.8/site-packages/sqlalchemy/engine/base.py", line 3374, in _wrap_pool_connect
    Connection._handle_dbapi_exception_noconnection(
  File "/home/airflow/.local/lib/python3.8/site-packages/sqlalchemy/engine/base.py", line 2208, in _handle_dbapi_exception_noconnection
    util.raise_(
  File "/home/airflow/.local/lib/python3.8/site-packages/sqlalchemy/util/compat.py", line 211, in raise_
    raise exception
  File "/home/airflow/.local/lib/python3.8/site-packages/sqlalchemy/engine/base.py", line 3371, in _wrap_pool_connect
    return fn()
  File "/home/airflow/.local/lib/python3.8/site-packages/sqlalchemy/pool/base.py", line 327, in connect
    return _ConnectionFairy._checkout(self)
  File "/home/airflow/.local/lib/python3.8/site-packages/sqlalchemy/pool/base.py", line 894, in _checkout
    fairy = _ConnectionRecord.checkout(pool)
  File "/home/airflow/.local/lib/python3.8/site-packages/sqlalchemy/pool/base.py", line 493, in checkout
    rec = pool._do_get()
  File "/home/airflow/.local/lib/python3.8/site-packages/sqlalchemy/pool/impl.py", line 146, in _do_get
    self._dec_overflow()
  File "/home/airflow/.local/lib/python3.8/site-packages/sqlalchemy/util/langhelpers.py", line 70, in __exit__
    compat.raise_(
  File "/home/airflow/.local/lib/python3.8/site-packages/sqlalchemy/util/compat.py", line 211, in raise_
    raise exception
  File "/home/airflow/.local/lib/python3.8/site-packages/sqlalchemy/pool/impl.py", line 143, in _do_get
    return self._create_connection()
  File "/home/airflow/.local/lib/python3.8/site-packages/sqlalchemy/pool/base.py", line 273, in _create_connection
    return _ConnectionRecord(self)
  File "/home/airflow/.local/lib/python3.8/site-packages/sqlalchemy/pool/base.py", line 388, in __init__
    self.__connect()
  File "/home/airflow/.local/lib/python3.8/site-packages/sqlalchemy/pool/base.py", line 691, in __connect
    pool.logger.debug("Error on connect(): %s", e)
  File "/home/airflow/.local/lib/python3.8/site-packages/sqlalchemy/util/langhelpers.py", line 70, in __exit__
    compat.raise_(
  File "/home/airflow/.local/lib/python3.8/site-packages/sqlalchemy/util/compat.py", line 211, in raise_
    raise exception
  File "/home/airflow/.local/lib/python3.8/site-packages/sqlalchemy/pool/base.py", line 686, in __connect
    self.dbapi_connection = connection = pool._invoke_creator(self)
  File "/home/airflow/.local/lib/python3.8/site-packages/sqlalchemy/engine/create.py", line 574, in connect
    return dialect.connect(*cargs, **cparams)
  File "/home/airflow/.local/lib/python3.8/site-packages/sqlalchemy/engine/default.py", line 598, in connect
    return self.dbapi.connect(*cargs, **cparams)
  File "/home/airflow/.local/lib/python3.8/site-packages/pymysql/connections.py", line 361, in __init__
    self.connect()
  File "/home/airflow/.local/lib/python3.8/site-packages/pymysql/connections.py", line 669, in connect
    self._request_authentication()
  File "/home/airflow/.local/lib/python3.8/site-packages/pymysql/connections.py", line 979, in _request_authentication
    auth_packet = _auth.caching_sha2_password_auth(self, auth_packet)
  File "/home/airflow/.local/lib/python3.8/site-packages/pymysql/_auth.py", line 268, in caching_sha2_password_auth
    pkt = _roundtrip(conn, data)
  File "/home/airflow/.local/lib/python3.8/site-packages/pymysql/_auth.py", line 121, in _roundtrip
    pkt = conn._read_packet()
  File "/home/airflow/.local/lib/python3.8/site-packages/pymysql/connections.py", line 775, in _read_packet
    packet.raise_for_error()
  File "/home/airflow/.local/lib/python3.8/site-packages/pymysql/protocol.py", line 219, in raise_for_error
    err.raise_mysql_exception(self._data)
  File "/home/airflow/.local/lib/python3.8/site-packages/pymysql/err.py", line 150, in raise_mysql_exception
    raise errorclass(errno, errval)
sqlalchemy.exc.OperationalError: (pymysql.err.OperationalError) (1045, "Access denied for user 'db_user'@'172.20.0.6' (using password: YES)")
(Background on this error at: https://sqlalche.me/e/14/e3q8)
[2024-12-15T00:18:19.648-0500] {taskinstance.py:1400} INFO - Marking task as FAILED. dag_id=create_daily_price_volume_table, task_id=create_price_volume_table, execution_date=20241215T050729, start_date=20241215T051819, end_date=20241215T051819
[2024-12-15T00:18:19.654-0500] {standard_task_runner.py:104} ERROR - Failed to execute job 286 for task create_price_volume_table ((pymysql.err.OperationalError) (1045, "Access denied for user 'db_user'@'172.20.0.6' (using password: YES)")
(Background on this error at: https://sqlalche.me/e/14/e3q8); 162)
[2024-12-15T00:18:19.675-0500] {local_task_job_runner.py:228} INFO - Task exited with return code 1
[2024-12-15T00:18:19.685-0500] {taskinstance.py:2778} INFO - 0 downstream tasks scheduled from follow-on schedule check
