[2024-12-14T04:25:30.834+0000] {taskinstance.py:1159} INFO - Dependencies all met for dep_context=non-requeueable deps ti=<TaskInstance: daily_price_volume_etl.fetch_data scheduled__2024-12-13T00:00:00+00:00 [queued]>
[2024-12-14T04:25:30.838+0000] {taskinstance.py:1159} INFO - Dependencies all met for dep_context=requeueable deps ti=<TaskInstance: daily_price_volume_etl.fetch_data scheduled__2024-12-13T00:00:00+00:00 [queued]>
[2024-12-14T04:25:30.838+0000] {taskinstance.py:1361} INFO - Starting attempt 1 of 2
[2024-12-14T04:25:30.845+0000] {taskinstance.py:1382} INFO - Executing <Task(PythonOperator): fetch_data> on 2024-12-13 00:00:00+00:00
[2024-12-14T04:25:30.848+0000] {standard_task_runner.py:57} INFO - Started process 98 to run task
[2024-12-14T04:25:30.850+0000] {standard_task_runner.py:84} INFO - Running: ['***', 'tasks', 'run', 'daily_price_volume_etl', 'fetch_data', 'scheduled__2024-12-13T00:00:00+00:00', '--job-id', '3', '--raw', '--subdir', 'DAGS_FOLDER/etl_dag.py', '--cfg-path', '/tmp/tmpuhm8xi8m']
[2024-12-14T04:25:30.851+0000] {standard_task_runner.py:85} INFO - Job 3: Subtask fetch_data
[2024-12-14T04:25:30.873+0000] {task_command.py:416} INFO - Running <TaskInstance: daily_price_volume_etl.fetch_data scheduled__2024-12-13T00:00:00+00:00 [running]> on host f6f2451b973c
[2024-12-14T04:25:30.960+0000] {taskinstance.py:1662} INFO - Exporting env vars: AIRFLOW_CTX_DAG_OWNER='***' AIRFLOW_CTX_DAG_ID='daily_price_volume_etl' AIRFLOW_CTX_TASK_ID='fetch_data' AIRFLOW_CTX_EXECUTION_DATE='2024-12-13T00:00:00+00:00' AIRFLOW_CTX_TRY_NUMBER='1' AIRFLOW_CTX_DAG_RUN_ID='scheduled__2024-12-13T00:00:00+00:00'
[2024-12-14T04:25:30.961+0000] {taskinstance.py:1937} ERROR - Task failed with exception
Traceback (most recent call last):
  File "/home/airflow/.local/lib/python3.8/site-packages/airflow/operators/python.py", line 192, in execute
    return_value = self.execute_callable()
  File "/home/airflow/.local/lib/python3.8/site-packages/airflow/operators/python.py", line 209, in execute_callable
    return self.python_callable(*self.op_args, **self.op_kwargs)
TypeError: fetch_data() missing 1 required positional argument: 'self'
[2024-12-14T04:25:30.963+0000] {taskinstance.py:1400} INFO - Marking task as UP_FOR_RETRY. dag_id=daily_price_volume_etl, task_id=fetch_data, execution_date=20241213T000000, start_date=20241214T042530, end_date=20241214T042530
[2024-12-14T04:25:30.968+0000] {standard_task_runner.py:104} ERROR - Failed to execute job 3 for task fetch_data (fetch_data() missing 1 required positional argument: 'self'; 98)
[2024-12-14T04:25:30.990+0000] {local_task_job_runner.py:228} INFO - Task exited with return code 1
[2024-12-14T04:25:31.003+0000] {taskinstance.py:2778} INFO - 0 downstream tasks scheduled from follow-on schedule check
