[2024-12-15T00:26:06.591-0500] {taskinstance.py:1159} INFO - Dependencies all met for dep_context=non-requeueable deps ti=<TaskInstance: daily_price_volume_etl.retry_missing_tickers manual__2024-12-15T05:23:58.814570+00:00 [queued]>
[2024-12-15T00:26:06.597-0500] {taskinstance.py:1159} INFO - Dependencies all met for dep_context=requeueable deps ti=<TaskInstance: daily_price_volume_etl.retry_missing_tickers manual__2024-12-15T05:23:58.814570+00:00 [queued]>
[2024-12-15T00:26:06.598-0500] {taskinstance.py:1361} INFO - Starting attempt 1 of 3
[2024-12-15T00:26:06.604-0500] {taskinstance.py:1382} INFO - Executing <Task(PythonOperator): retry_missing_tickers> on 2024-12-15 05:23:58.814570+00:00
[2024-12-15T00:26:06.608-0500] {standard_task_runner.py:57} INFO - Started process 1157 to run task
[2024-12-15T00:26:06.610-0500] {standard_task_runner.py:84} INFO - Running: ['***', 'tasks', 'run', 'daily_price_volume_etl', 'retry_missing_tickers', 'manual__2024-12-15T05:23:58.814570+00:00', '--job-id', '296', '--raw', '--subdir', 'DAGS_FOLDER/etl_dag.py', '--cfg-path', '/tmp/tmp7paz321i']
[2024-12-15T00:26:06.613-0500] {standard_task_runner.py:85} INFO - Job 296: Subtask retry_missing_tickers
[2024-12-15T00:26:06.685-0500] {task_command.py:416} INFO - Running <TaskInstance: daily_price_volume_etl.retry_missing_tickers manual__2024-12-15T05:23:58.814570+00:00 [running]> on host ee093ddf7dd7
[2024-12-15T00:26:06.754-0500] {taskinstance.py:1662} INFO - Exporting env vars: AIRFLOW_CTX_DAG_OWNER='***' AIRFLOW_CTX_DAG_ID='daily_price_volume_etl' AIRFLOW_CTX_TASK_ID='retry_missing_tickers' AIRFLOW_CTX_EXECUTION_DATE='2024-12-15T05:23:58.814570+00:00' AIRFLOW_CTX_TRY_NUMBER='1' AIRFLOW_CTX_DAG_RUN_ID='manual__2024-12-15T05:23:58.814570+00:00'
[2024-12-15T00:26:20.913-0500] {multi.py:176} ERROR - 
2 Failed downloads:
[2024-12-15T00:26:20.913-0500] {multi.py:189} ERROR - [']', '[']: YFTzMissingError('$%ticker%: possibly delisted; no timezone found')
[2024-12-15T00:26:20.917-0500] {etl.py:69} ERROR - No data downloaded
[2024-12-15T00:26:20.917-0500] {etl.py:114} ERROR - Missing column: Ticker
[2024-12-15T00:26:20.917-0500] {etl.py:226} ERROR - ETL Transformation failed: Validation Error
[2024-12-15T00:26:20.917-0500] {taskinstance.py:1937} ERROR - Task failed with exception
Traceback (most recent call last):
  File "/opt/airflow/dags/src/etl.py", line 201, in transform_pipeline
    raise ValueError(f"Validation Error")
ValueError: Validation Error

During handling of the above exception, another exception occurred:

Traceback (most recent call last):
  File "/home/airflow/.local/lib/python3.8/site-packages/airflow/operators/python.py", line 192, in execute
    return_value = self.execute_callable()
  File "/home/airflow/.local/lib/python3.8/site-packages/airflow/operators/python.py", line 209, in execute_callable
    return self.python_callable(*self.op_args, **self.op_kwargs)
  File "/opt/airflow/dags/src/etl.py", line 375, in run_daily_pipeline
    df,missing_tickers =  transform_pipeline(df,all_tickers = tickers)
  File "/opt/airflow/dags/src/etl.py", line 227, in transform_pipeline
    raise ValueError("Transformation failed")
ValueError: Transformation failed
[2024-12-15T00:26:20.923-0500] {taskinstance.py:1400} INFO - Marking task as UP_FOR_RETRY. dag_id=daily_price_volume_etl, task_id=retry_missing_tickers, execution_date=20241215T052358, start_date=20241215T052606, end_date=20241215T052620
[2024-12-15T00:26:20.932-0500] {standard_task_runner.py:104} ERROR - Failed to execute job 296 for task retry_missing_tickers (Transformation failed; 1157)
[2024-12-15T00:26:20.950-0500] {local_task_job_runner.py:228} INFO - Task exited with return code 1
[2024-12-15T00:26:20.959-0500] {taskinstance.py:2778} INFO - 0 downstream tasks scheduled from follow-on schedule check
