[2024-12-14T22:36:31.716-0500] {taskinstance.py:1159} INFO - Dependencies all met for dep_context=non-requeueable deps ti=<TaskInstance: daily_price_volume_etl.retry_missing_tickers manual__2024-12-15T03:35:11.349355+00:00 [queued]>
[2024-12-14T22:36:31.722-0500] {taskinstance.py:1159} INFO - Dependencies all met for dep_context=requeueable deps ti=<TaskInstance: daily_price_volume_etl.retry_missing_tickers manual__2024-12-15T03:35:11.349355+00:00 [queued]>
[2024-12-14T22:36:31.722-0500] {taskinstance.py:1361} INFO - Starting attempt 1 of 3
[2024-12-14T22:36:31.730-0500] {taskinstance.py:1382} INFO - Executing <Task(PythonOperator): retry_missing_tickers> on 2024-12-15 03:35:11.349355+00:00
[2024-12-14T22:36:31.733-0500] {standard_task_runner.py:57} INFO - Started process 618 to run task
[2024-12-14T22:36:31.735-0500] {standard_task_runner.py:84} INFO - Running: ['***', 'tasks', 'run', 'daily_price_volume_etl', 'retry_missing_tickers', 'manual__2024-12-15T03:35:11.349355+00:00', '--job-id', '62', '--raw', '--subdir', 'DAGS_FOLDER/etl_dag.py', '--cfg-path', '/tmp/tmplyivjx2r']
[2024-12-14T22:36:31.737-0500] {standard_task_runner.py:85} INFO - Job 62: Subtask retry_missing_tickers
[2024-12-14T22:36:31.758-0500] {task_command.py:416} INFO - Running <TaskInstance: daily_price_volume_etl.retry_missing_tickers manual__2024-12-15T03:35:11.349355+00:00 [running]> on host f15d24439435
[2024-12-14T22:36:31.795-0500] {taskinstance.py:1662} INFO - Exporting env vars: AIRFLOW_CTX_DAG_OWNER='***' AIRFLOW_CTX_DAG_ID='daily_price_volume_etl' AIRFLOW_CTX_TASK_ID='retry_missing_tickers' AIRFLOW_CTX_EXECUTION_DATE='2024-12-15T03:35:11.349355+00:00' AIRFLOW_CTX_TRY_NUMBER='1' AIRFLOW_CTX_DAG_RUN_ID='manual__2024-12-15T03:35:11.349355+00:00'
[2024-12-14T22:36:49.169-0500] {base.py:128} ERROR - Failed to get ticker ']' reason: HTTPSConnectionPool(host='sg.yahoo.com', port=443): Max retries exceeded with url: /?p=us (Caused by SSLError(SSLEOFError(8, 'EOF occurred in violation of protocol (_ssl.c:1131)')))
[2024-12-14T22:36:55.856-0500] {multi.py:176} ERROR - 
2 Failed downloads:
[2024-12-14T22:36:55.857-0500] {multi.py:189} ERROR - [']', '[']: YFTzMissingError('$%ticker%: possibly delisted; no timezone found')
[2024-12-14T22:36:55.868-0500] {etl.py:69} ERROR - No data downloaded
[2024-12-14T22:36:55.870-0500] {etl.py:114} ERROR - Missing column: Ticker
[2024-12-14T22:36:55.870-0500] {etl.py:226} ERROR - ETL Transformation failed: Validation Error
[2024-12-14T22:36:55.871-0500] {taskinstance.py:1937} ERROR - Task failed with exception
Traceback (most recent call last):
  File "/opt/airflow/dags/src/etl.py", line 201, in transform_pipeline
    raise ValueError(f"Validation Error")
ValueError: Validation Error

During handling of the above exception, another exception occurred:

Traceback (most recent call last):
  File "/home/airflow/.local/lib/python3.8/site-packages/airflow/operators/python.py", line 192, in execute
    return_value = self.execute_callable()
  File "/home/airflow/.local/lib/python3.8/site-packages/airflow/operators/python.py", line 209, in execute_callable
    return self.python_callable(*self.op_args, **self.op_kwargs)
  File "/opt/airflow/dags/src/etl.py", line 375, in run_daily_pipeline
    df,missing_tickers =  transform_pipeline(df,all_tickers = tickers)
  File "/opt/airflow/dags/src/etl.py", line 227, in transform_pipeline
    raise ValueError("Transformation failed")
ValueError: Transformation failed
[2024-12-14T22:36:55.880-0500] {taskinstance.py:1400} INFO - Marking task as UP_FOR_RETRY. dag_id=daily_price_volume_etl, task_id=retry_missing_tickers, execution_date=20241215T033511, start_date=20241215T033631, end_date=20241215T033655
[2024-12-14T22:36:55.892-0500] {standard_task_runner.py:104} ERROR - Failed to execute job 62 for task retry_missing_tickers (Transformation failed; 618)
[2024-12-14T22:36:55.915-0500] {local_task_job_runner.py:228} INFO - Task exited with return code 1
[2024-12-14T22:36:55.924-0500] {taskinstance.py:2778} INFO - 0 downstream tasks scheduled from follow-on schedule check
