[2024-12-15T00:26:04.808-0500] {taskinstance.py:1159} INFO - Dependencies all met for dep_context=non-requeueable deps ti=<TaskInstance: daily_price_volume_etl.retry_missing_tickers scheduled__2024-12-14T00:00:00+00:00 [queued]>
[2024-12-15T00:26:04.812-0500] {taskinstance.py:1159} INFO - Dependencies all met for dep_context=requeueable deps ti=<TaskInstance: daily_price_volume_etl.retry_missing_tickers scheduled__2024-12-14T00:00:00+00:00 [queued]>
[2024-12-15T00:26:04.812-0500] {taskinstance.py:1361} INFO - Starting attempt 1 of 3
[2024-12-15T00:26:04.819-0500] {taskinstance.py:1382} INFO - Executing <Task(PythonOperator): retry_missing_tickers> on 2024-12-14 00:00:00+00:00
[2024-12-15T00:26:04.823-0500] {standard_task_runner.py:57} INFO - Started process 1152 to run task
[2024-12-15T00:26:04.825-0500] {standard_task_runner.py:84} INFO - Running: ['***', 'tasks', 'run', 'daily_price_volume_etl', 'retry_missing_tickers', 'scheduled__2024-12-14T00:00:00+00:00', '--job-id', '295', '--raw', '--subdir', 'DAGS_FOLDER/etl_dag.py', '--cfg-path', '/tmp/tmpnm47ydpt']
[2024-12-15T00:26:04.827-0500] {standard_task_runner.py:85} INFO - Job 295: Subtask retry_missing_tickers
[2024-12-15T00:26:04.857-0500] {task_command.py:416} INFO - Running <TaskInstance: daily_price_volume_etl.retry_missing_tickers scheduled__2024-12-14T00:00:00+00:00 [running]> on host ee093ddf7dd7
[2024-12-15T00:26:04.905-0500] {taskinstance.py:1662} INFO - Exporting env vars: AIRFLOW_CTX_DAG_OWNER='***' AIRFLOW_CTX_DAG_ID='daily_price_volume_etl' AIRFLOW_CTX_TASK_ID='retry_missing_tickers' AIRFLOW_CTX_EXECUTION_DATE='2024-12-14T00:00:00+00:00' AIRFLOW_CTX_TRY_NUMBER='1' AIRFLOW_CTX_DAG_RUN_ID='scheduled__2024-12-14T00:00:00+00:00'
[2024-12-15T00:26:23.349-0500] {base.py:128} ERROR - Failed to get ticker ']' reason: HTTPSConnectionPool(host='sg.yahoo.com', port=443): Max retries exceeded with url: /?p=us (Caused by SSLError(SSLEOFError(8, 'EOF occurred in violation of protocol (_ssl.c:1131)')))
[2024-12-15T00:26:29.717-0500] {multi.py:176} ERROR - 
2 Failed downloads:
[2024-12-15T00:26:29.719-0500] {multi.py:189} ERROR - [']', '[']: YFTzMissingError('$%ticker%: possibly delisted; no timezone found')
[2024-12-15T00:26:29.723-0500] {etl.py:69} ERROR - No data downloaded
[2024-12-15T00:26:29.723-0500] {etl.py:114} ERROR - Missing column: Ticker
[2024-12-15T00:26:29.723-0500] {etl.py:226} ERROR - ETL Transformation failed: Validation Error
[2024-12-15T00:26:29.724-0500] {taskinstance.py:1937} ERROR - Task failed with exception
Traceback (most recent call last):
  File "/opt/airflow/dags/src/etl.py", line 201, in transform_pipeline
    raise ValueError(f"Validation Error")
ValueError: Validation Error

During handling of the above exception, another exception occurred:

Traceback (most recent call last):
  File "/home/airflow/.local/lib/python3.8/site-packages/airflow/operators/python.py", line 192, in execute
    return_value = self.execute_callable()
  File "/home/airflow/.local/lib/python3.8/site-packages/airflow/operators/python.py", line 209, in execute_callable
    return self.python_callable(*self.op_args, **self.op_kwargs)
  File "/opt/airflow/dags/src/etl.py", line 375, in run_daily_pipeline
    df,missing_tickers =  transform_pipeline(df,all_tickers = tickers)
  File "/opt/airflow/dags/src/etl.py", line 227, in transform_pipeline
    raise ValueError("Transformation failed")
ValueError: Transformation failed
[2024-12-15T00:26:29.731-0500] {taskinstance.py:1400} INFO - Marking task as UP_FOR_RETRY. dag_id=daily_price_volume_etl, task_id=retry_missing_tickers, execution_date=20241214T000000, start_date=20241215T052604, end_date=20241215T052629
[2024-12-15T00:26:29.741-0500] {standard_task_runner.py:104} ERROR - Failed to execute job 295 for task retry_missing_tickers (Transformation failed; 1152)
[2024-12-15T00:26:29.765-0500] {local_task_job_runner.py:228} INFO - Task exited with return code 1
[2024-12-15T00:26:29.774-0500] {taskinstance.py:2778} INFO - 0 downstream tasks scheduled from follow-on schedule check
