[2024-12-15T15:43:56.214-0500] {taskinstance.py:1159} INFO - Dependencies all met for dep_context=non-requeueable deps ti=<TaskInstance: daily_price_volume_etl.transform_data manual__2024-12-15T20:29:32.493974+00:00 [queued]>
[2024-12-15T15:43:56.218-0500] {taskinstance.py:1159} INFO - Dependencies all met for dep_context=requeueable deps ti=<TaskInstance: daily_price_volume_etl.transform_data manual__2024-12-15T20:29:32.493974+00:00 [queued]>
[2024-12-15T15:43:56.218-0500] {taskinstance.py:1361} INFO - Starting attempt 3 of 3
[2024-12-15T15:43:56.224-0500] {taskinstance.py:1382} INFO - Executing <Task(PythonOperator): transform_data> on 2024-12-15 20:29:32.493974+00:00
[2024-12-15T15:43:56.227-0500] {standard_task_runner.py:57} INFO - Started process 669 to run task
[2024-12-15T15:43:56.229-0500] {standard_task_runner.py:84} INFO - Running: ['***', 'tasks', 'run', 'daily_price_volume_etl', 'transform_data', 'manual__2024-12-15T20:29:32.493974+00:00', '--job-id', '427', '--raw', '--subdir', 'DAGS_FOLDER/etl_dag.py', '--cfg-path', '/tmp/tmpauw30_dx']
[2024-12-15T15:43:56.231-0500] {standard_task_runner.py:85} INFO - Job 427: Subtask transform_data
[2024-12-15T15:43:56.257-0500] {task_command.py:416} INFO - Running <TaskInstance: daily_price_volume_etl.transform_data manual__2024-12-15T20:29:32.493974+00:00 [running]> on host 1e0c6de054af
[2024-12-15T15:43:56.308-0500] {taskinstance.py:1662} INFO - Exporting env vars: AIRFLOW_CTX_DAG_OWNER='***' AIRFLOW_CTX_DAG_ID='daily_price_volume_etl' AIRFLOW_CTX_TASK_ID='transform_data' AIRFLOW_CTX_EXECUTION_DATE='2024-12-15T20:29:32.493974+00:00' AIRFLOW_CTX_TRY_NUMBER='3' AIRFLOW_CTX_DAG_RUN_ID='manual__2024-12-15T20:29:32.493974+00:00'
[2024-12-15T15:43:56.314-0500] {taskinstance.py:1937} ERROR - Task failed with exception
Traceback (most recent call last):
  File "/home/airflow/.local/lib/python3.8/site-packages/airflow/operators/python.py", line 192, in execute
    return_value = self.execute_callable()
  File "/home/airflow/.local/lib/python3.8/site-packages/airflow/operators/python.py", line 209, in execute_callable
    return self.python_callable(*self.op_args, **self.op_kwargs)
  File "/opt/airflow/dags/src/etl.py", line 421, in transform_and_save_data
    raw_df = pd.read_csv(raw_data_path)
  File "/home/airflow/.local/lib/python3.8/site-packages/pandas/io/parsers/readers.py", line 912, in read_csv
    return _read(filepath_or_buffer, kwds)
  File "/home/airflow/.local/lib/python3.8/site-packages/pandas/io/parsers/readers.py", line 577, in _read
    parser = TextFileReader(filepath_or_buffer, **kwds)
  File "/home/airflow/.local/lib/python3.8/site-packages/pandas/io/parsers/readers.py", line 1407, in __init__
    self._engine = self._make_engine(f, self.engine)
  File "/home/airflow/.local/lib/python3.8/site-packages/pandas/io/parsers/readers.py", line 1661, in _make_engine
    self.handles = get_handle(
  File "/home/airflow/.local/lib/python3.8/site-packages/pandas/io/common.py", line 859, in get_handle
    handle = open(
FileNotFoundError: [Errno 2] No such file or directory: '/opt/airflow/dags/src/../../landing_zone/daily_price_volume_etl/fetch_raw_data/2024-12-15T20:29:32.493974+00:00raw_data.csv'
[2024-12-15T15:43:56.320-0500] {taskinstance.py:1400} INFO - Marking task as FAILED. dag_id=daily_price_volume_etl, task_id=transform_data, execution_date=20241215T202932, start_date=20241215T204356, end_date=20241215T204356
[2024-12-15T15:43:56.326-0500] {standard_task_runner.py:104} ERROR - Failed to execute job 427 for task transform_data ([Errno 2] No such file or directory: '/opt/airflow/dags/src/../../landing_zone/daily_price_volume_etl/fetch_raw_data/2024-12-15T20:29:32.493974+00:00raw_data.csv'; 669)
[2024-12-15T15:43:56.370-0500] {local_task_job_runner.py:228} INFO - Task exited with return code 1
