[2024-12-15T15:33:28.916-0500] {taskinstance.py:1159} INFO - Dependencies all met for dep_context=non-requeueable deps ti=<TaskInstance: daily_price_volume_etl.transform_data manual__2024-12-15T20:29:32.493974+00:00 [queued]>
[2024-12-15T15:33:28.925-0500] {taskinstance.py:1159} INFO - Dependencies all met for dep_context=requeueable deps ti=<TaskInstance: daily_price_volume_etl.transform_data manual__2024-12-15T20:29:32.493974+00:00 [queued]>
[2024-12-15T15:33:28.925-0500] {taskinstance.py:1361} INFO - Starting attempt 1 of 3
[2024-12-15T15:33:28.932-0500] {taskinstance.py:1382} INFO - Executing <Task(PythonOperator): transform_data> on 2024-12-15 20:29:32.493974+00:00
[2024-12-15T15:33:28.935-0500] {standard_task_runner.py:57} INFO - Started process 1651 to run task
[2024-12-15T15:33:28.937-0500] {standard_task_runner.py:84} INFO - Running: ['***', 'tasks', 'run', 'daily_price_volume_etl', 'transform_data', 'manual__2024-12-15T20:29:32.493974+00:00', '--job-id', '416', '--raw', '--subdir', 'DAGS_FOLDER/etl_dag.py', '--cfg-path', '/tmp/tmp1q74964h']
[2024-12-15T15:33:28.939-0500] {standard_task_runner.py:85} INFO - Job 416: Subtask transform_data
[2024-12-15T15:33:28.965-0500] {task_command.py:416} INFO - Running <TaskInstance: daily_price_volume_etl.transform_data manual__2024-12-15T20:29:32.493974+00:00 [running]> on host c8ba26a29f48
[2024-12-15T15:33:29.005-0500] {taskinstance.py:1662} INFO - Exporting env vars: AIRFLOW_CTX_DAG_OWNER='***' AIRFLOW_CTX_DAG_ID='daily_price_volume_etl' AIRFLOW_CTX_TASK_ID='transform_data' AIRFLOW_CTX_EXECUTION_DATE='2024-12-15T20:29:32.493974+00:00' AIRFLOW_CTX_TRY_NUMBER='1' AIRFLOW_CTX_DAG_RUN_ID='manual__2024-12-15T20:29:32.493974+00:00'
[2024-12-15T15:33:29.070-0500] {taskinstance.py:1937} ERROR - Task failed with exception
Traceback (most recent call last):
  File "/home/airflow/.local/lib/python3.8/site-packages/airflow/operators/python.py", line 192, in execute
    return_value = self.execute_callable()
  File "/home/airflow/.local/lib/python3.8/site-packages/airflow/operators/python.py", line 209, in execute_callable
    return self.python_callable(*self.op_args, **self.op_kwargs)
  File "/opt/airflow/dags/src/etl.py", line 428, in transform_and_save_data
    df = transform_pipeline(raw_df)
TypeError: transform_pipeline() missing 1 required positional argument: 'all_tickers'
[2024-12-15T15:33:29.075-0500] {taskinstance.py:1400} INFO - Marking task as UP_FOR_RETRY. dag_id=daily_price_volume_etl, task_id=transform_data, execution_date=20241215T202932, start_date=20241215T203328, end_date=20241215T203329
[2024-12-15T15:33:29.081-0500] {standard_task_runner.py:104} ERROR - Failed to execute job 416 for task transform_data (transform_pipeline() missing 1 required positional argument: 'all_tickers'; 1651)
[2024-12-15T15:33:29.122-0500] {local_task_job_runner.py:228} INFO - Task exited with return code 1
