[2024-12-15T15:08:13.932-0500] {taskinstance.py:1159} INFO - Dependencies all met for dep_context=non-requeueable deps ti=<TaskInstance: daily_price_volume_etl.get_missing_tikers manual__2024-12-15T20:00:11.741288+00:00 [queued]>
[2024-12-15T15:08:13.936-0500] {taskinstance.py:1159} INFO - Dependencies all met for dep_context=requeueable deps ti=<TaskInstance: daily_price_volume_etl.get_missing_tikers manual__2024-12-15T20:00:11.741288+00:00 [queued]>
[2024-12-15T15:08:13.936-0500] {taskinstance.py:1361} INFO - Starting attempt 2 of 3
[2024-12-15T15:08:13.942-0500] {taskinstance.py:1382} INFO - Executing <Task(PythonOperator): get_missing_tikers> on 2024-12-15 20:00:11.741288+00:00
[2024-12-15T15:08:13.945-0500] {standard_task_runner.py:57} INFO - Started process 65 to run task
[2024-12-15T15:08:13.947-0500] {standard_task_runner.py:84} INFO - Running: ['***', 'tasks', 'run', 'daily_price_volume_etl', 'get_missing_tikers', 'manual__2024-12-15T20:00:11.741288+00:00', '--job-id', '367', '--raw', '--subdir', 'DAGS_FOLDER/etl_dag.py', '--cfg-path', '/tmp/tmpcuw3o_l4']
[2024-12-15T15:08:13.949-0500] {standard_task_runner.py:85} INFO - Job 367: Subtask get_missing_tikers
[2024-12-15T15:08:13.973-0500] {task_command.py:416} INFO - Running <TaskInstance: daily_price_volume_etl.get_missing_tikers manual__2024-12-15T20:00:11.741288+00:00 [running]> on host ce140fab26a5
[2024-12-15T15:08:14.067-0500] {taskinstance.py:1662} INFO - Exporting env vars: AIRFLOW_CTX_DAG_OWNER='***' AIRFLOW_CTX_DAG_ID='daily_price_volume_etl' AIRFLOW_CTX_TASK_ID='get_missing_tikers' AIRFLOW_CTX_EXECUTION_DATE='2024-12-15T20:00:11.741288+00:00' AIRFLOW_CTX_TRY_NUMBER='2' AIRFLOW_CTX_DAG_RUN_ID='manual__2024-12-15T20:00:11.741288+00:00'
[2024-12-15T15:08:14.074-0500] {taskinstance.py:1937} ERROR - Task failed with exception
Traceback (most recent call last):
  File "/home/airflow/.local/lib/python3.8/site-packages/airflow/operators/python.py", line 192, in execute
    return_value = self.execute_callable()
  File "/home/airflow/.local/lib/python3.8/site-packages/airflow/operators/python.py", line 209, in execute_callable
    return self.python_callable(*self.op_args, **self.op_kwargs)
  File "/opt/airflow/dags/src/etl.py", line 415, in get_missing_tikers
    raw_df = pd.read_csv(raw_data_path)
  File "/home/airflow/.local/lib/python3.8/site-packages/pandas/io/parsers/readers.py", line 912, in read_csv
    return _read(filepath_or_buffer, kwds)
  File "/home/airflow/.local/lib/python3.8/site-packages/pandas/io/parsers/readers.py", line 577, in _read
    parser = TextFileReader(filepath_or_buffer, **kwds)
  File "/home/airflow/.local/lib/python3.8/site-packages/pandas/io/parsers/readers.py", line 1407, in __init__
    self._engine = self._make_engine(f, self.engine)
  File "/home/airflow/.local/lib/python3.8/site-packages/pandas/io/parsers/readers.py", line 1661, in _make_engine
    self.handles = get_handle(
  File "/home/airflow/.local/lib/python3.8/site-packages/pandas/io/common.py", line 716, in get_handle
    ioargs = _get_filepath_or_buffer(
  File "/home/airflow/.local/lib/python3.8/site-packages/pandas/io/common.py", line 456, in _get_filepath_or_buffer
    raise ValueError(msg)
ValueError: Invalid file path or buffer object type: <class 'NoneType'>
[2024-12-15T15:08:14.080-0500] {taskinstance.py:1400} INFO - Marking task as UP_FOR_RETRY. dag_id=daily_price_volume_etl, task_id=get_missing_tikers, execution_date=20241215T200011, start_date=20241215T200813, end_date=20241215T200814
[2024-12-15T15:08:14.085-0500] {standard_task_runner.py:104} ERROR - Failed to execute job 367 for task get_missing_tikers (Invalid file path or buffer object type: <class 'NoneType'>; 65)
[2024-12-15T15:08:14.127-0500] {local_task_job_runner.py:228} INFO - Task exited with return code 1
[2024-12-15T15:08:14.136-0500] {taskinstance.py:2778} INFO - 0 downstream tasks scheduled from follow-on schedule check
